### Java 面试题：`finally` 语句块一定会执行吗？

在 Java 中，`finally` 块是用于包含必须执行的代码的一个特殊块。无论是否抛出异常，`finally` 块中的代码都会被执行。然而，也有一些特殊情况会导致 `finally` 块不被执行。

#### `finally` 块的作用

`finally` 块主要用于释放资源，比如关闭文件流、数据库连接或其他需要显式关闭的资源。即使在 `try` 或 `catch` 块中发生了异常，`finally` 块中的代码也会被执行，除非程序被中断或退出。

#### 不执行 `finally` 块的情况

1. **程序退出**：如果在 `finally` 块之前调用了 `System.exit()` 方法，程序将立即退出，`finally` 块不会被执行。
2. **线程中断**：如果线程被中断 (`Thread.interrupted()` 或 `Thread.currentThread().interrupt()`)，`finally` 块可能不会被执行。
3. **死锁**：如果程序处于死锁状态，`finally` 块也不会被执行。

#### 示例代码

下面通过几个例子来展示 `finally` 块的执行情况：

##### 示例 1：正常执行

```java
public class FinallyBlockExample {

    public static void main(String[] args) {
        try {
            System.out.println("Inside try block.");
            // 不抛出异常
        } finally {
            System.out.println("Finally block executed.");
        }
    }
}
```

输出结果：

```
Inside try block.
Finally block executed.
```

##### 示例 2：抛出异常

```java
public class FinallyBlockExample {

    public static void main(String[] args) {
        try {
            System.out.println("Inside try block.");
            throw new RuntimeException("Exception thrown!");
        } catch (RuntimeException e) {
            System.out.println("Caught exception: " + e.getMessage());
        } finally {
            System.out.println("Finally block executed.");
        }
    }
}
```

输出结果：

```
Inside try block.
Caught exception: Exception thrown!
Finally block executed.
```

##### 示例 3：调用 `System.exit()`

```java
public class FinallyBlockExample {

    public static void main(String[] args) {
        try {
            System.out.println("Inside try block.");
            System.exit(1); // 立即退出程序
        } finally {
            System.out.println("This line will not be printed.");
        }
    }
}
```

输出结果：

```
Inside try block.
```

在这个例子中，`System.exit(1)` 会立即终止程序，因此 `finally` 块中的代码不会被执行。

##### 示例 4：线程中断

```java
public class FinallyBlockExample {

    public static void main(String[] args) throws InterruptedException {
        Thread thread = new Thread(() -> {
            try {
                System.out.println("Inside try block.");
                Thread.sleep(1000); // 模拟长时间运行的任务
            } catch (InterruptedException e) {
                System.out.println("Thread interrupted.");
            } finally {
                System.out.println("Finally block executed.");
            }
        });

        thread.start();
        Thread.sleep(100); // 等待一段时间后中断线程
        thread.interrupt(); // 中断线程
    }
}
```

输出结果：

```
Inside try block.
Thread interrupted.
Finally block executed.
```

在这个例子中，主线程等待了一段时间后中断了工作线程。尽管线程被中断，但 `finally` 块还是被执行了，因为它是在 `catch` 块之后。

#### 更深入的拓展

1. **资源管理**：

   - 使用 `try-with-resources` 语句可以自动关闭实现了 `AutoCloseable` 接口的资源，简化了代码。如果资源没有正确关闭，可能会导致资源泄露等问题。

   ```java
   import java.io.FileInputStream;
   import java.io.IOException;

   public class ResourceManagementExample {

       public static void main(String[] args) {
           try (FileInputStream fis = new FileInputStream("example.txt")) {
               // 使用资源
               System.out.println("Resource used.");
           } catch (IOException e) {
               e.printStackTrace();
           }
       }
   }
   ```

2. **异常链**：

   - 在 `finally` 块中抛出的异常会覆盖之前的异常，形成异常链。可以通过 `throw new Exception(e)` 来保留原始异常信息。

   ```java
   public class ExceptionChainExample {

       public static void main(String[] args) {
           try {
               throw new RuntimeException("First exception.");
           } catch (RuntimeException e) {
               System.out.println("Caught first exception.");
           } finally {
               throw new RuntimeException("Second exception.");
           }
       }
   }
   ```

   输出结果：

   ```
   Caught first exception.
   java.lang.RuntimeException: Second exception.
   at ExceptionChainExample.main(ExceptionChainExample.java:13)
   ```

3. **异常处理的策略**：

   - 在 `finally` 块中可以进行异常的重新抛出或记录日志等操作，确保程序的健壮性和可维护性。

4. **多线程环境下的 `finally` 块**：
   - 在多线程环境中，如果线程被中断，`finally` 块依然会被执行，除非线程在 `finally` 块之前被中断。

### 总结

`finally` 块通常会在 `try` 或 `catch` 块执行完毕后执行，无论是否有异常发生。然而，在一些特殊情况下，如程序退出或线程中断，`finally` 块可能不会被执行。理解 `finally` 块的执行机制以及如何正确使用它对于编写健壮的 Java 程序非常重要。通过适当的异常处理和资源管理策略，可以提高程序的可靠性和性能。
